Workbook
Name Slicer_Location1: #N/A
Name Slicer_Price_Category: #N/A
Name Slicer_Price_Category1: #N/A
Name Slicer_Property_Type: #N/A
Name Slicer_Year__Colomn1: #N/A

Sheet Raw_Data
A1: Property_ID | B1: Listing_Date | C1: Property_Type | D1: Location | E1: Size_Sqm | F1: Bedrooms | G1: Price
A2: PRP0045 | B2: 46033 | C2: Apartment | D2: Hargeisa | E2: 59 | F2: 5 | G2: 33315.8
A3: PRP0188 | B3: 46142 | D3: Baidoa | E3: 185 | F3: 1 | G3: 66750.47
B4: 45699 | C4: Villa | D4: Mogadishu | E4: 400 | F4: 5 | G4: 372852.18
A5: PRP0212 | C5: House | D5: Mogadishu | E5: 284 | F5: 3 | G5: 187104.95
A6: PRP0141 | B6: 46009 | C6: Commercial | D6: Hargeisa | F6: 0 | G6: 283316.37
A7: PRP0230 | B7: 46132 | C7: Apartment | D7: Mogadishu | F7: 6 | G7: 58741.9
A8: PRP0255 | B8: 46197 | C8: Apartment | D8: Baidoa | E8: 146 | G8: 64417.58
A9: PRP0208 | B9: 46168 | C9: Apartment | D9: Mogadishu | E9: 50 | G9: 44214.57
A10: PRP0273 | B10: 46043 | C10: Apartment | D10: Baidoa | E10: 56 | F10: 2 | G10: 18933.72
A11: PRP0016 | B11: 45855 | C11: Commercial | D11: Baidoa | E11: 374 | F11: 0 | G11: 167091.21
A12: PRP0062 | B12: 45982 | D12: Mogadishu | E12: 186 | F12: 4 | G12: 154685.01
A13: PRP0091 | B13: 46108 | D13: Hargeisa | E13: 1005 | F13: N/A | G13: 380318.1
A14: PRP0197 | B14: 45979 | C14: Apartment | D14: Mogadishu | E14: 135 | F14: 1 | G14: 85595.89
A15: PRP0137 | B15: 45862 | C15: Apartment | D15: Hargeisa | E15: 69 | F15: 6 | G15: 53710.9
B16: 45820 | C16: Apartment | D16: Mogadishu | E16: 153 | F16: 5 | G16: 94612.52
A17: PRP0168 | B17: 46038 | C17: Apartment | D17: Mogadishu | E17: 84 | F17: 4 | G17: 69993.85
A18: PRP0025 | B18: 45662 | C18: Land | D18: Baidoa | E18: 540 | F18: 0 | G18: 175133.17
A19: PRP0118 | B19: 46195 | C19: House | D19: Mogadishu | E19: 124 | F19: 6 | G19: 87390.52
A20: PRP0276 | C20: Apartment | D20: Mogadishu | E20: 106 | F20: 4 | G20: 97362.81
A21: PRP0149 | B21: 46127 | C21: Apartment | D21: Mogadishu | E21: 78 | F21: 4 | G21: 59333.36
A22: PRP0223 | B22: 45707 | C22: Apartment | D22: Hargeisa | E22: 86 | F22: 6 | G22: 61674.83
A23: PRP0159 | B23: 45851 | C23: Land | D23: Mogadishu | E23: 813 | F23: 0 | G23: 505246.4
A24: PRP0287 | C24: Commercial | D24: Mogadishu | E24: 82 | F24: 0 | G24: NULL
A25: PRP0122 | B25: 45756 | C25: House | D25: Hargeisa | F25: 3 | G25: 109022.54
A26: PRP0267 | B26: 45929 | C26: House | D26: Mogadishu | E26: 126 | F26: 2 | G26: 80684.99
A27: PRP0169 | B27: 46017 | C27: Land | D27: garowe | E27: 1131 | F27: 0 | G27: 436421.06
A28: PRP0245 | B28: 46055 | C28: Villa | D28: Bosaso | E28: 241 | F28: 5 | G28: 205954.15
A29: PRP0112 | B29: 45999 | C29: Apartment | D29: Kismayo | E29: 165 | F29: 3 | G29: 71013.35
B30: 46107 | C30: Villa | D30: Garowe | E30: 246 | F30: 4 | G30: 189700.22
A31: PRP0003 | B31: 46157 | C31: House | D31: Kismayo | E31: 269 | F31: 5 | G31: 117783.73
A32: PRP0177 | B32: 45822 | C32: Villa | D32: Mogadishu | E32: 428 | F32: 4 | G32: 423951.96
A33: PRP0081 | B33: 46130 | C33: House | D33: Bosaso | E33: 118 | F33: 2 | G33: 64706.06
A34: PRP0018 | B34: 46187 | D34: Bosaso | E34: 375 | F34: 0 | G34: 360319.2
A35: PRP0187 | B35: 46216 | C35: Land | D35: Baidoa | F35: 0 | G35: 258143.66
A36: PRP0269 | B36: 45865 | C36: House | D36: Hargeisa | E36: 91 | F36: 2 | G36: 67703.18
A37: PRP0072 | B37: 46225 | C37: Villa | D37: Hargeisa | E37: 432 | F37: 1
A38: PRP0196 | B38: 45844 | C38: House | E38: 233 | F38: 4 | G38: 204504.39
A39: PRP0155 | B39: 45711 | C39: Commercial | D39: Baidoa | F39: 0 | G39: 299493.28
A40: PRP0277 | B40: 45974 | C40: Commercial | D40: Baidoa | E40: 428 | F40: 0 | G40: 244310.76
...

Sheet Clean_Data
A1: Property_ID | B1: Listing_Date | C1: Property_Type | D1: Location | E1: Size_Sqm | F1: Bedrooms | G1: Price | H1: Price_Category | I1: Days Since Listing | J1: ID_Extracted | K1: Location Length | L1: Standardized | M1: Standardized2 | N1: Year _Colomn
A2: PRP0045 | B2: 46033 | C2: Apartment | D2: Hargeisa | E2: 59 | F2: 5 | G2: 33315.8 | H2: =_xlfn.IFS(G2>=200000,"High",G2>=100000,"Medium",G2<100000,"Low") -> Low | I2: =IF(OR(B2="Unknown",B2=""),"Unknown",TODAY()-B2) -> 226 | J2: =RIGHT(A2,4) -> 0045 | K2: =LEN(D2) -> 8 | L2: =PROPER(C2) -> Apartment | M2: =PROPER(D2) -> Hargeisa | N2: =IF(B2="Unknown","Unknown",YEAR(B2)) -> 2026
A3: PRP0188 | B3: 46142 | C3: Unknown | D3: Baidoa | E3: 185 | F3: 1 | G3: 66750.47 | H3: =_xlfn.IFS(G3>=200000,"High",G3>=100000,"Medium",G3<100000,"Low") -> Low | I3: =IF(OR(B3="Unknown",B3=""),"Unknown",TODAY()-B3) -> 117 | J3: =RIGHT(A3,4) -> 0188 | K3: =LEN(D3) -> 6 | L3: =PROPER(C3) -> Unknown | M3: =PROPER(D3) -> Baidoa | N3: =IF(B3="Unknown","Unknown",YEAR(B3)) -> 2026
A4: Unknown01 | B4: 45699 | C4: Villa | D4: Mogadishu | E4: 400 | F4: 5 | G4: 372852.18 | H4: =_xlfn.IFS(G4>=200000,"High",G4>=100000,"Medium",G4<100000,"Low") -> High | I4: =IF(OR(B4="Unknown",B4=""),"Unknown",TODAY()-B4) -> 560 | J4: =RIGHT(A4,4) -> wn01 | K4: =LEN(D4) -> 9 | L4: =PROPER(C4) -> Villa | M4: =PROPER(D4) -> Mogadishu | N4: =IF(B4="Unknown","Unknown",YEAR(B4)) -> 2025
A5: PRP0212 | B5: Unknown | C5: House | D5: Mogadishu | E5: 284 | F5: 3 | G5: 187104.95 | H5: =_xlfn.IFS(G5>=200000,"High",G5>=100000,"Medium",G5<100000,"Low") -> Medium | I5: =IF(OR(B5="Unknown",B5=""),"Unknown",TODAY()-B5) -> Unknown | J5: =RIGHT(A5,4) -> 0212 | K5: =LEN(D5) -> 9 | L5: =PROPER(C5) -> House | M5: =PROPER(D5) -> Mogadishu | N5: =IF(B5="Unknown","Unknown",YEAR(B5)) -> Unknown
A6: PRP0141 | B6: 46009 | C6: Commercial | D6: Hargeisa | E6: 295 | F6: 0 | G6: 283316.37 | H6: =_xlfn.IFS(G6>=200000,"High",G6>=100000,"Medium",G6<100000,"Low") -> High | I6: =IF(OR(B6="Unknown",B6=""),"Unknown",TODAY()-B6) -> 250 | J6: =RIGHT(A6,4) -> 0141 | K6: =LEN(D6) -> 8 | L6: =PROPER(C6) -> Commercial | M6: =PROPER(D6) -> Hargeisa | N6: =IF(B6="Unknown","Unknown",YEAR(B6)) -> 2025
A7: PRP0230 | B7: 46132 | C7: Apartment | D7: Mogadishu | E7: 295 | F7: 6 | G7: 58741.9 | H7: =_xlfn.IFS(G7>=200000,"High",G7>=100000,"Medium",G7<100000,"Low") -> Low | I7: =IF(OR(B7="Unknown",B7=""),"Unknown",TODAY()-B7) -> 127 | J7: =RIGHT(A7,4) -> 0230 | K7: =LEN(D7) -> 9 | L7: =PROPER(C7) -> Apartment | M7: =PROPER(D7) -> Mogadishu | N7: =IF(B7="Unknown","Unknown",YEAR(B7)) -> 2026
A8: PRP0255 | B8: 46197 | C8: Apartment | D8: Baidoa | E8: 146 | F8: 3 | G8: 64417.58 | H8: =_xlfn.IFS(G8>=200000,"High",G8>=100000,"Medium",G8<100000,"Low") -> Low | I8: =IF(OR(B8="Unknown",B8=""),"Unknown",TODAY()-B8) -> 62 | J8: =RIGHT(A8,4) -> 0255 | K8: =LEN(D8) -> 6 | L8: =PROPER(C8) -> Apartment | M8: =PROPER(D8) -> Baidoa | N8: =IF(B8="Unknown","Unknown",YEAR(B8)) -> 2026
A9: PRP0208 | B9: 46168 | C9: Apartment | D9: Mogadishu | E9: 50 | F9: 3 | G9: 44214.57 | H9: =_xlfn.IFS(G9>=200000,"High",G9>=100000,"Medium",G9<100000,"Low") -> Low | I9: =IF(OR(B9="Unknown",B9=""),"Unknown",TODAY()-B9) -> 91 | J9: =RIGHT(A9,4) -> 0208 | K9: =LEN(D9) -> 9 | L9: =PROPER(C9) -> Apartment | M9: =PROPER(D9) -> Mogadishu | N9: =IF(B9="Unknown","Unknown",YEAR(B9)) -> 2026
A10: PRP0273 | B10: 46043 | C10: Apartment | D10: Baidoa | E10: 56 | F10: 2 | G10: 18933.72 | H10: =_xlfn.IFS(G10>=200000,"High",G10>=100000,"Medium",G10<100000,"Low") -> Low | I10: =IF(OR(B10="Unknown",B10=""),"Unknown",TODAY()-B10) -> 216 | J10: =RIGHT(A10,4) -> 0273 | K10: =LEN(D10) -> 6 | L10: =PROPER(C10) -> Apartment | M10: =PROPER(D10) -> Baidoa | N10: =IF(B10="Unknown","Unknown",YEAR(B10)) -> 2026
A11: PRP0016 | B11: 45855 | C11: Commercial | D11: Baidoa | E11: 374 | F11: 0 | G11: 167091.21 | H11: =_xlfn.IFS(G11>=200000,"High",G11>=100000,"Medium",G11<100000,"Low") -> Medium | I11: =IF(OR(B11="Unknown",B11=""),"Unknown",TODAY()-B11) -> 404 | J11: =RIGHT(A11,4) -> 0016 | K11: =LEN(D11) -> 6 | L11: =PROPER(C11) -> Commercial | M11: =PROPER(D11) -> Baidoa | N11: =IF(B11="Unknown","Unknown",YEAR(B11)) -> 2025
A12: PRP0062 | B12: 45982 | C12: Unknown | D12: Mogadishu | E12: 186 | F12: 4 | G12: 154685.01 | H12: =_xlfn.IFS(G12>=200000,"High",G12>=100000,"Medium",G12<100000,"Low") -> Medium | I12: =IF(OR(B12="Unknown",B12=""),"Unknown",TODAY()-B12) -> 277 | J12: =RIGHT(A12,4) -> 0062 | K12: =LEN(D12) -> 9 | L12: =PROPER(C12) -> Unknown | M12: =PROPER(D12) -> Mogadishu | N12: =IF(B12="Unknown","Unknown",YEAR(B12)) -> 2025
A13: PRP0091 | B13: 46108 | C13: Unknown | D13: Hargeisa | E13: 1005 | F13: 3 | G13: 380318.1 | H13: =_xlfn.IFS(G13>=200000,"High",G13>=100000,"Medium",G13<100000,"Low") -> High | I13: =IF(OR(B13="Unknown",B13=""),"Unknown",TODAY()-B13) -> 151 | J13: =RIGHT(A13,4) -> 0091 | K13: =LEN(D13) -> 8 | L13: =PROPER(C13) -> Unknown | M13: =PROPER(D13) -> Hargeisa | N13: =IF(B13="Unknown","Unknown",YEAR(B13)) -> 2026
A14: PRP0197 | B14: 45979 | C14: Apartment | D14: Mogadishu | E14: 135 | F14: 1 | G14: 85595.89 | H14: =_xlfn.IFS(G14>=200000,"High",G14>=100000,"Medium",G14<100000,"Low") -> Low | I14: =IF(OR(B14="Unknown",B14=""),"Unknown",TODAY()-B14) -> 280 | J14: =RIGHT(A14,4) -> 0197 | K14: =LEN(D14) -> 9 | L14: =PROPER(C14) -> Apartment | M14: =PROPER(D14) -> Mogadishu | N14: =IF(B14="Unknown","Unknown",YEAR(B14)) -> 2025
A15: PRP0137 | B15: 45862 | C15: Apartment | D15: Hargeisa | E15: 69 | F15: 6 | G15: 53710.9 | H15: =_xlfn.IFS(G15>=200000,"High",G15>=100000,"Medium",G15<100000,"Low") -> Low | I15: =IF(OR(B15="Unknown",B15=""),"Unknown",TODAY()-B15) -> 397 | J15: =RIGHT(A15,4) -> 0137 | K15: =LEN(D15) -> 8 | L15: =PROPER(C15) -> Apartment | M15: =PROPER(D15) -> Hargeisa | N15: =IF(B15="Unknown","Unknown",YEAR(B15)) -> 2025
A16: Unknown02 | B16: 45820 | C16: Apartment | D16: Mogadishu | E16: 153 | F16: 5 | G16: 94612.52 | H16: =_xlfn.IFS(G16>=200000,"High",G16>=100000,"Medium",G16<100000,"Low") -> Low | I16: =IF(OR(B16="Unknown",B16=""),"Unknown",TODAY()-B16) -> 439 | J16: =RIGHT(A16,4) -> wn02 | K16: =LEN(D16) -> 9 | L16: =PROPER(C16) -> Apartment | M16: =PROPER(D16) -> Mogadishu | N16: =IF(B16="Unknown","Unknown",YEAR(B16)) -> 2025
A17: PRP0168 | B17: 46038 | C17: Apartment | D17: Mogadishu | E17: 84 | F17: 4 | G17: 69993.85 | H17: =_xlfn.IFS(G17>=200000,"High",G17>=100000,"Medium",G17<100000,"Low") -> Low | I17: =IF(OR(B17="Unknown",B17=""),"Unknown",TODAY()-B17) -> 221 | J17: =RIGHT(A17,4) -> 0168 | K17: =LEN(D17) -> 9 | L17: =PROPER(C17) -> Apartment | M17: =PROPER(D17) -> Mogadishu | N17: =IF(B17="Unknown","Unknown",YEAR(B17)) -> 2026
... A19: PRP0118 | B19: 46195 | C19: House | D19: Mogadishu | E19: 124 | F19: 6 | G19: 87390.52 | H19: =_xlfn.IFS(G19>=200000,"High",G19>=100000,"Medium",G19<100000,"Low") -> Low | I19: =IF(OR(B19="Unknown",B19=""),"Unknown",TODAY()-B19) -> 64 | J19: =RIGHT(A19,4) -> 0118 | K19: =LEN(D19) -> 9 | L19: =PROPER(C19) -> House | M19: =PROPER(D19) -> Mogadishu | N19: =IF(B19="Unknown","Unknown",YEAR(B19)) -> 2026
A20: PRP0276 | B20: Unknown | C20: Apartment | D20: Mogadishu | E20: 106 | F20: 4 | G20: 97362.81 | H20: =_xlfn.IFS(G20>=200000,"High",G20>=100000,"Medium",G20<100000,"Low") -> Low | I20: =IF(OR(B20="Unknown",B20=""),"Unknown",TODAY()-B20) -> Unknown | J20: =RIGHT(A20,4) -> 0276 | K20: =LEN(D20) -> 9 | L20: =PROPER(C20) -> Apartment | M20: =PROPER(D20) -> Mogadishu | N20: =IF(B20="Unknown","Unknown",YEAR(B20)) -> Unknown
A21: PRP0149 | B21: 46127 | C21: Apartment | D21: Mogadishu | E21: 78 | F21: 4 | G21: 59333.36 | H21: =_xlfn.IFS(G21>=200000,"High",G21>=100000,"Medium",G21<100000,"Low") -> Low | I21: =IF(OR(B21="Unknown",B21=""),"Unknown",TODAY()-B21) -> 132 | J21: =RIGHT(A21,4) -> 0149 | K21: =LEN(D21) -> 9 | L21: =PROPER(C21) -> Apartment | M21: =PROPER(D21) -> Mogadishu | N21: =IF(B21="Unknown","Unknown",YEAR(B21)) -> 2026
A22: PRP0223 | B22: 45707 | C22: Apartment | D22: Hargeisa | E22: 86 | F22: 6 | G22: 61674.83 | H22: =_xlfn.IFS(G22>=200000,"High",G22>=100000,"Medium",G22<100000,"Low") -> Low | I22: =IF(OR(B22="Unknown",B22=""),"Unknown",TODAY()-B22) -> 552 | J22: =RIGHT(A22,4) -> 0223 | K22: =LEN(D22) -> 8 | L22: =PROPER(C22) -> Apartment | M22: =PROPER(D22) -> Hargeisa | N22: =IF(B22="Unknown","Unknown",YEAR(B22)) -> 2025
A23: PRP0159 | B23: 45851 | C23: Land | D23: Mogadishu | E23: 813 | F23: 0 | G23: 505246.4 | H23: =_xlfn.IFS(G23>=200000,"High",G23>=100000,"Medium",G23<100000,"Low") -> High | I23: =IF(OR(B23="Unknown",B23=""),"Unknown",TODAY()-B23) -> 408 | J23: =RIGHT(A23,4) -> 0159 | K23: =LEN(D23) -> 9 | L23: =PROPER(C23) -> Land | M23: =PROPER(D23) -> Mogadishu | N23: =IF(B23="Unknown","Unknown",YEAR(B23)) -> 2025
A24: PRP0287 | B24: Unknown | C24: Commercial | D24: Mogadishu | E24: 82 | F24: 0 | G24: 178260.23 | H24: =_xlfn.IFS(G24>=200000,"High",G24>=100000,"Medium",G24<100000,"Low") -> Medium | I24: =IF(OR(B24="Unknown",B24=""),"Unknown",TODAY()-B24) -> Unknown | J24: =RIGHT(A24,4) -> 0287 | K24: =LEN(D24) -> 9 | L24: =PROPER(C24) -> Commercial | M24: =PROPER(D24) -> Mogadishu | N24: =IF(B24="Unknown","Unknown",YEAR(B24)) -> Unknown
A25: PRP0122 | B25: 45756 | C25: House | D25: Hargeisa | E25: 295 | F25: 3 | G25: 109022.54 | H25: =_xlfn.IFS(G25>=200000,"High",G25>=100000,"Medium",G25<100000,"Low") -> Medium | I25: =IF(OR(B25="Unknown",B25=""),"Unknown",TODAY()-B25) -> 503 | J25: =RIGHT(A25,4) -> 0122 | K25: =LEN(D25) -> 8 | L25: =PROPER(C25) -> House | M25: =PROPER(D25) -> Hargeisa | N25: =IF(B25="Unknown","Unknown",YEAR(B25)) -> 2025
A26: PRP0267 | B26: 45929 | C26: House | D26: Mogadishu | E26: 126 | F26: 2 | G26: 80684.99 | H26: =_xlfn.IFS(G26>=200000,"High",G26>=100000,"Medium",G26<100000,"Low") -> Low | I26: =IF(OR(B26="Unknown",B26=""),"Unknown",TODAY()-B26) -> 330 | J26: =RIGHT(A26,4) -> 0267 | K26: =LEN(D26) -> 9 | L26: =PROPER(C26) -> House | M26: =PROPER(D26) -> Mogadishu | N26: =IF(B26="Unknown","Unknown",YEAR(B26)) -> 2025
A27: PRP0169 | B27: 46017 | C27: Land | D27: Garowe | E27: 1131 | F27: 0 | G27: 436421.06 | H27: =_xlfn.IFS(G27>=200000,"High",G27>=100000,"Medium",G27<100000,"Low") -> High | I27: =IF(OR(B27="Unknown",B27=""),"Unknown",TODAY()-B27) -> 242 | J27: =RIGHT(A27,4) -> 0169 | K27: =LEN(D27) -> 6 | L27: =PROPER(C27) -> Land | M27: =PROPER(D27) -> Garowe | N27: =IF(B27="Unknown","Unknown",YEAR(B27)) -> 2025
A28: PRP0245 | B28: 46055 | C28: Villa | D28: Bosaso | E28: 241 | F28: 5 | G28: 205954.15 | H28: =_xlfn.IFS(G28>=200000,"High",G28>=100000,"Medium",G28<100000,"Low") -> High | I28: =IF(OR(B28="Unknown",B28=""),"Unknown",TODAY()-B28) -> 204 | J28: =RIGHT(A28,4) -> 0245 | K28: =LEN(D28) -> 6 | L28: =PROPER(C28) -> Villa | M28: =PROPER(D28) -> Bosaso | N28: =IF(B28="Unknown","Unknown",YEAR(B28)) -> 2026
A29: PRP0112 | B29: 45999 | C29: Apartment | D29: Kismayo | E29: 165 | F29: 3 | G29: 71013.35 | H29: =_xlfn.IFS(G29>=200000,"High",G29>=100000,"Medium",G29<100000,"Low") -> Low | I29: =IF(OR(B29="Unknown",B29=""),"Unknown",TODAY()-B29) -> 260 | J29: =RIGHT(A29,4) -> 0112 | K29: =LEN(D29) -> 7 | L29: =PROPER(C29) -> Apartment | M29: =PROPER(D29) -> Kismayo | N29: =IF(B29="Unknown","Unknown",YEAR(B29)) -> 2025
A30: Unknown03 | B30: 46107 | C30: Villa | D30: Garowe | E30: 246 | F30: 4 | G30: 189700.22 | H30: =_xlfn.IFS(G30>=200000,"High",G30>=100000,"Medium",G30<100000,"Low") -> Medium | I30: =IF(OR(B30="Unknown",B30=""),"Unknown",TODAY()-B30) -> 152 | J30: =RIGHT(A30,4) -> wn03 | K30: =LEN(D30) -> 6 | L30: =PROPER(C30) -> Villa | M30: =PROPER(D30) -> Garowe | N30: =IF(B30="Unknown","Unknown",YEAR(B30)) -> 2026
A31: PRP0003 | B31: 46157 | C31: House | D31: Kismayo | E31: 269 | F31: 5 | G31: 117783.73 | H31: =_xlfn.IFS(G31>=200000,"High",G31>=100000,"Medium",G31<100000,"Low") -> Medium | I31: =IF(OR(B31="Unknown",B31=""),"Unknown",TODAY()-B31) -> 102 | J31: =RIGHT(A31,4) -> 0003 | K31: =LEN(D31) -> 7 | L31: =PROPER(C31) -> House | M31: =PROPER(D31) -> Kismayo | N31: =IF(B31="Unknown","Unknown",YEAR(B31)) -> 2026
A32: PRP0177 | B32: 45822 | C32: Villa | D32: Mogadishu | E32: 428 | F32: 4 | G32: 423951.96 | H32: =_xlfn.IFS(G32>=200000,"High",G32>=100000,"Medium",G32<100000,"Low") -> High | I32: =IF(OR(B32="Unknown",B32=""),"Unknown",TODAY()-B32) -> 437 | J32: =RIGHT(A32,4) -> 0177 | K32: =LEN(D32) -> 9 | L32: =PROPER(C32) -> Villa | M32: =PROPER(D32) -> Mogadishu | N32: =IF(B32="Unknown","Unknown",YEAR(B32)) -> 2025
A33: PRP0081 | B33: 46130 | C33: House | D33: Bosaso | E33: 118 | F33: 2 | G33: 64706.06 | H33: =_xlfn.IFS(G33>=200000,"High",G33>=100000,"Medium",G33<100000,"Low") -> Low | I33: =IF(OR(B33="Unknown",B33=""),"Unknown",TODAY()-B33) -> 129 | J33: =RIGHT(A33,4) -> 0081 | K33: =LEN(D33) -> 6 | L33: =PROPER(C33) -> House | M33: =PROPER(D33) -> Bosaso | N33: =IF(B33="Unknown","Unknown",YEAR(B33)) -> 2026
A34: PRP0018 | B34: 46187 | C34: Unknown | D34: Bosaso | E34: 375 | F34: 0 | G34: 360319.2 | H34: =_xlfn.IFS(G34>=200000,"High",G34>=100000,"Medium",G34<100000,"Low") -> High | I34: =IF(OR(B34="Unknown",B34=""),"Unknown",TODAY()-B34) -> 72 | J34: =RIGHT(A34,4) -> 0018 | K34: =LEN(D34) -> 6 | L34: =PROPER(C34) -> Unknown | M34: =PROPER(D34) -> Bosaso | N34: =IF(B34="Unknown","Unknown",YEAR(B34)) -> 2026
A35: PRP0187 | B35: 46216 | C35: Land | D35: Baidoa | E35: 295 | F35: 0 | G35: 258143.66 | H35: =_xlfn.IFS(G35>=200000,"High",G35>=100000,"Medium",G35<100000,"Low") -> High | I35: =IF(OR(B35="Unknown",B35=""),"Unknown",TODAY()-B35) -> 43 | J35: =RIGHT(A35,4) -> 0187 | K35: =LEN(D35) -> 6 | L35: =PROPER(C35) -> Land | M35: =PROPER(D35) -> Baidoa | N35: =IF(B35="Unknown","Unknown",YEAR(B35)) -> 2026
A36: PRP0269 | B36: 45865 | C36: House | D36: Hargeisa | E36: 91 | F36: 2 | G36: 67703.18 | H36: =_xlfn.IFS(G36>=200000,"High",G36>=100000,"Medium",G36<100000,"Low") -> Low | I36: =IF(OR(B36="Unknown",B36=""),"Unknown",TODAY()-B36) -> 394 | J36: =RIGHT(A36,4) -> 0269 | K36: =LEN(D36) -> 8 | L36: =PROPER(C36) -> House | M36: =PROPER(D36) -> Hargeisa | N36: =IF(B36="Unknown","Unknown",YEAR(B36)) -> 2025
... A70: PRP0182 | B70: 45905 | C70: Villa | D70: Mogadishu | E70: 211 | F70: 2 | G70: 209482.86 | H70: =_xlfn.IFS(G70>=200000,"High",G70>=100000,"Medium",G70<100000,"Low") -> High | I70: =IF(OR(B70="Unknown",B70=""),"Unknown",TODAY()-B70) -> 354 | J70: =RIGHT(A70,4) -> 0182 | K70: =LEN(D70) -> 9 | L70: =PROPER(C70) -> Villa | M70: =PROPER(D70) -> Mogadishu | N70: =IF(B70="Unknown","Unknown",YEAR(B70)) -> 2025
A71: PRP0268 | B71: Unknown | C71: Land | D71: Baidoa | E71: 1078 | F71: 0 | G71: 340698.41 | H71: =_xlfn.IFS(G71>=200000,"High",G71>=100000,"Medium",G71<100000,"Low") -> High | I71: =IF(OR(B71="Unknown",B71=""),"Unknown",TODAY()-B71) -> Unknown | J71: =RIGHT(A71,4) -> 0268 | K71: =LEN(D71) -> 6 | L71: =PROPER(C71) -> Land | M71: =PROPER(D71) -> Baidoa | N71: =IF(B71="Unknown","Unknown",YEAR(B71)) -> Unknown
A72: PRP0262 | B72: 45722 | C72: Apartment | D72: Mogadishu | E72: 172 | F72: 3 | G72: 170994.69 | H72: =_xlfn.IFS(G72>=200000,"High",G72>=100000,"Medium",G72<100000,"Low") -> Medium | I72: =IF(OR(B72="Unknown",B72=""),"Unknown",TODAY()-B72) -> 537 | J72: =RIGHT(A72,4) -> 0262 | K72: =LEN(D72) -> 9 | L72: =PROPER(C72) -> Apartment | M72: =PROPER(D72) -> Mogadishu | N72: =IF(B72="Unknown","Unknown",YEAR(B72)) -> 2025
A73: PRP0031 | B73: 46157 | C73: Land | D73: Garowe | E73: 883 | F73: 0 | G73: 375425.55 | H73: =_xlfn.IFS(G73>=200000,"High",G73>=100000,"Medium",G73<100000,"Low") -> High | I73: =IF(OR(B73="Unknown",B73=""),"Unknown",TODAY()-B73) -> 102 | J73: =RIGHT(A73,4) -> 0031 | K73: =LEN(D73) -> 6 | L73: =PROPER(C73) -> Land | M73: =PROPER(D73) -> Garowe | N73: =IF(B73="Unknown","Unknown",YEAR(B73)) -> 2026
A74: PRP0080 | B74: 46070 | C74: Commercial | D74: Mogadishu | E74: 69 | F74: 0 | G74: 91262.04 | H74: =_xlfn.IFS(G74>=200000,"High",G74>=100000,"Medium",G74<100000,"Low") -> Low | I74: =IF(OR(B74="Unknown",B74=""),"Unknown",TODAY()-B74) -> 189 | J74: =RIGHT(A74,4) -> 0080 | K74: =LEN(D74) -> 9 | L74: =PROPER(C74) -> Commercial | M74: =PROPER(D74) -> Mogadishu | N74: =IF(B74="Unknown","Unknown",YEAR(B74)) -> 2026
...

Sheet Analysis
E1: DATA QUALITY SUMMARY
B3: BEFORE CLEANING | E3: AFTER CLEANING | H3: CLEANING STATUS
B4: Quality Check | C4: Result | E4: Quality Check | F4: Result | H4: Item | I4: Status
B5: Total Records | C5: 300 | E5: Total Records | F5: =COUNTA(Clean_Data!A2:A301) -> 292 | H5: Duplicates Removed | I5: Completed
B6: Duplicate Records | C6: 8 | E6: Duplicate Records | F6: 0 | H6: Missing Values Handled | I6: Completed
B7: Blank Rows | C7: 0 | E7: Blank Rows | F7: 0 | H7: Inconsistent Values Corrected | I7: Completed
B8: Missing Values | C8: 111 | E8: Missing Values | F8: 0 | H8: Text Cleaning | I8: Completed
C10: PROPERTY ANALYSIS SUMMARY | G10: SUMMARY MISSING
B12: Metric | C12: Value | F12: Metric | G12: Value
B13: Total Properties | C13: =COUNTA(Clean_Data!A2:A1000) -> 292 | F13: Property_ID | G13: =COUNTBLANK(Raw_Data!A2:A301) -> 15
B14: total price | C14: =SUM(PropertyTable[Price]) -> 52230254 | F14: Listing_Date | G14: =COUNTBLANK(Raw_Data!B2:B301) -> 15
B15: Average Price | C15: =AVERAGE(Clean_Data!G2:G293) -> 178870.73 | F15: Property_Type | G15: =COUNTBLANK(Raw_Data!C2:C301) -> 17
B16: Minimum Price | C16: =MIN(Clean_Data!G2:G293) -> 17505.31 | F16: Location | G16: =COUNTBLANK(Raw_Data!D2:D301) -> 18
B17: Maximum Price | C17: =MAX(Clean_Data!G2:G293) -> 2000022 | F17: Size_Sqm | G17: =COUNTBLANK(Raw_Data!E2:E301) -> 15
B18: Average Size (sqm) | C18: =AVERAGE(Clean_Data!E2:E293) -> 294.5274 | F18: Bedrooms | G18: =COUNTBLANK(Raw_Data!F2:F301) -> 16
B19: Average Bedrooms | C19: =AVERAGE(Clean_Data!F2:F293) -> 2.6267123 | F19: Price | G19: =COUNTBLANK(Raw_Data!G2:G301) -> 15
B20: Price Range | C20: =MAX(Clean_Data!G2:G293)-MIN(Clean_Data!G2:G293) -> 1982516.7 | F20: Total | G20: =SUM(G13:G19) -> 111
B21: 2025 Properties | C21: =COUNTIFS(PropertyTable[Listing_Date],">="&DATE(2025,1,1),PropertyTable[Listing_Date],"<"&DATE(2026,1,1)) -> 169
B22: 2026 Properties | C22: =COUNTIFS(PropertyTable[Listing_Date],">="&DATE(2026,1,1),PropertyTable[Listing_Date],"<"&DATE(2027,1,1)) -> 107
B23: Most Common Type | C23: =INDEX(Clean_Data!C2:C293,MODE(MATCH(Clean_Data!C2:C293,Clean_Data!C2:C293,0))) -> Apartment
B24: Top Location | C24: =INDEX(Clean_Data!D2:D293,MODE(MATCH(Clean_Data!D2:D293,Clean_Data!D2:D293,0))) -> Mogadishu
B25: High | C25: =COUNTIF(PropertyTable[Price_Category],"High") -> 85

Sheet PivotTables
A1: Properties by Location
A3: Row Labels | B3: Count of Property_ID
A4: Hargeisa | B4: 4
A5: Mogadishu | B5: 8
A6: Grand Total | B6: 12
A13: Property Type Distribution
A14: Row Labels | B14: Sum of Price
A15: Unknown | B15: 2496165.9
A16: Grand Total | B16: 2496165.9
A24: Average Price by Location
A26: Row Labels | B26: Average of Price
A27: Hargeisa | B27: 165454.05
A28: Mogadishu | B28: 229293.71
A29: Grand Total | B29: 208013.83
A37: Total Property Value by Type
A39: Row Labels | B39: Count of Property_ID
A40: Unknown | B40: 12
A41: Grand Total | B41: 12
A49: Total Property Size by Location
A50: Row Labels | B50: Sum of Size_Sqm
A51: Hargeisa | B51: 1481
A52: Mogadishu | B52: 2384
A53: Grand Total | B53: 3865
A63: Row Labels | B63: Sum of Bedrooms
A64: Hargeisa | B64: 11
A65: Mogadishu | B65: 20
A66: Grand Total | B66: 31
A81: Row Labels | B81: Average of Size_Sqm
A82: Hargeisa | B82: 370.25
A83: Mogadishu | B83: 298
A84: Grand Total | B84: 322.08333
A95: Row Labels | B95: Max of Price
A96: Hargeisa | B96: 380318.1
A97: Mogadishu | B97: 620677.11
A98: Grand Total | B98: 620677.11
A158: Row Labels
A159: Unknown
A160: 45662
A161: 45663
A162: 45665
...

Sheet Dashbroad_1
E1: REAL ESTATE DASHBOARD 1 – OVERVIEW
F2: Summary of Properties, Types, Prices and Locations
D4: TOTAL PROPERTIES | F4: AVERAGE PRICE | H4: AVERAGE SIZE | J4: HIGHEST PRICE
D6: =COUNTA(PropertyTable[Property_ID]) -> 292 | F6: =AVERAGEA(PropertyTable[Price]) -> 178870.73 | H6: =AVERAGEA(PropertyTable[Size_Sqm]) -> 294.5274 | J6: =MAX(PropertyTable[Price]) -> 2000022

Sheet Dashbroad_2
D1: REAL ESTATE DASHBOARD 2 – ANALYSIS
E2: Deeper Analysis of Price, Size, Bedrooms and Value
D4: TOTAL PROPERTIES | F4: TOTAL PROPERTY PRICE | H4: TOTAL BEDROOMS | K4: AVERAGE BEDROOMS
D6: =COUNTA(PropertyTable[Property_ID]) -> 292 | F6: =SUM(PropertyTable[Price]) -> 52230254 | H6: =SUM(PropertyTable[Bedrooms]) -> 767 | K6: =AVERAGEA(PropertyTable[Bedrooms]) -> 2.6267123

Sheet Findings
D1: FINDINGS & RECOMMENDATIONS
D2: Project: Real Estate Property Data Analysis | Dataset: Real Estate Property Data | Records analyzed: 292 (after cleaning)
A4: KEY FINDINGS
A5: 1. Mogadishu has the highest number of properties, with 101 listings, making it the largest market in the dataset.
A6: 2. Apartment is the most common property type, with 96 properties, followed by Houses with 59.
A7: 3. Mogadishu has the highest average property price, at about $209,588, slightly higher than Garowe at $206,754.
A8: 4. Data quality improved after cleaning; 8 duplicate records were removed and missing values were handled, leaving 292 clean records.
A10: RECOMMENDATIONS
A11: 1. Focus more on Mogadishu, because it has the largest number of properties and strong average prices.
A12: 2. Monitor the apartment market, since apartments make up the largest share of the available properties.
A13: 3. Review pricing by location, especially in Mogadishu and Garowe, to understand why their average prices are higher.
A14: 4. Keep the data regularly updated and cleaned to reduce missing, duplicate, and unknown information.
A16: SUMMARY
A17: Overall, the data shows that Mogadishu has the strongest property market, with the most listings and high average prices.
A18: Apartments are the most common property type, and the cleaned data is more reliable for analysis.
